Workbook
Name accesslist: 'AUG2022 FED'!$B$14:$R$97
Name in_week: IF(AND(today>='AUG2022 FED'!$B1,today<'AUG2022 FED'!$B2),TRUE,FALSE)
Name today: TODAY()
Name weeks: 'AUG2022 FED'!$B$17:$B$100

Sheet AUG2022 FED
A1: Course Start | G1: Legend
A2: Course Assignment | F2: AUTUMN SEMESTER | H2: Start Course
A3: Intake (Introduction) week | F3: SPRING SEMESTER | H3: Assessments
D4: FED Access list (Year 1 and Year 2) | W4: Total Students | Z4: =SUM(H10:L10)+SUM(R10:AH10)+N10+P10 -> 240
A5: S19 Study plan
A6: S21 Study plan
A7: S23 Study plan | C7: New Teams Classes (already on ✔︎) | E7: ✔︎ | G7: ✔︎ | H7: ✔︎ | I7: ✔︎ | L7: ✔︎ | N7: ✔︎ | O7: ✔︎ | P7: ✔︎ | Q7: ✔︎ | R7: ✔︎ | S7: ✔︎ | T7: ✔︎ | U7: ✔︎ | W7: ✔︎ | X7: ✔︎ | Y7: ✔︎ | Z7: ✔︎ | AA7: ✔︎ | AB7: ✔︎ | AC7: ✔︎ | AD7: ✔︎ | AE7: ✔︎ | AF7: ✔︎ | AG7: ✔︎ | AH7: ✔︎ | AI7: ✔︎ | AJ7: ✔︎ | AK7: ✔︎ | AL7: ✔︎
A8: S24 Study plan | C8: Open class / CA | Q8: X | S8: X | Y8: X | Z8: X | AA8: X | AB8: X | AC8: X | AD8: X
E9: 2021 CLASSES | I9: 2022 CLASSES | M9: 2023 CLASSES | U9: 2024 CLASSES | AC9: 2025 CLASSES | AK9: 2026 CLASSES
C10: Student numbers | E10: 0 | F10: 0 | G10: 0 | H10: 4 | I10: 4 | J10: 6 | K10: 10 | L10: 13 | M10: 0 | N10: 8 | O10: 0 | P10: 7 | Q10: 0 | R10: 14 | S10: 0 | T10: 2 | U10: 17 | V10: 7 | W10: 12 | X10: 2 | Y10: 39 | Z10: 11 | AA10: 5 | AB10: 4 | AC10: 18 | AD10: 4 | AE10: 16 | AF10: 5 | AG10: 26 | AH10: 6 | AI10: 7 | AJ10: 6 | AK10: 12 | AL10: 3 | AM10: 6 | AN10: 3
C11: Study plan | D11: S19 | E11: S19 | F11: S19 | G11: S21 | H11: S21 | I11: S21 | J11: S21 | K11: S21 | L11: S21 | M11: S21 | N11: S21 | O11: S21 | P11: S21 | Q11: S24 | R11: S23 | S11: S24 | T11: S24 | U11: S24 | V11: S24 | W11: S23 | X11: S23 | Y11: S24 | Z11: S24 | AA11: S24 | AB11: S24 | AC11: S24 | AD11: S24 | AE11: S25 | AF11: S24 | AG11: S25 | AH11: S25 | AI11: S25 | AJ11: S25 | AK11: S25 | AL11: S25 | AM11: S25 | AN11: S25 | AO11: S25 | AP11: S25 | AQ11: S25 | AR11: S25
C12: LMS | D12: Moodle | E12: Moodle | F12: Moodle | G12: Moodle | H12: Moodle | I12: Moodle | J12: New Moodle | K12: New Moodle | L12: New Moodle | M12: Moodle | N12: New Moodle | O12: Moodle | P12: New Moodle | Q12: Moodle | R12: New Moodle | S12: Moodle | T12: New Moodle | U12: Moodle | V12: New Moodle | W12: New Moodle | X12: New Moodle | Y12: New Moodle | Z12: New Moodle | AA12: New Moodle | AB12: New Moodle | AC12: New Moodle | AD12: New Moodle | AE12: New Moodle | AF12: New Moodle | AG12: New Moodle | AH12: New Moodle | AI12: New Moodle | AJ12: New Moodle | AK12: New Moodle | AL12: New Moodle | AM12: New Moodle | AN12: New Moodle | AO12: New Moodle | AP12: New Moodle | AQ12: New Moodle | AR12: New Moodle
J13: 2021-2023 version | K13: 2021-2023 version | L13: 2021-2023 version | N13: 2021-2023 version | P13: 2021-2023 version
B14: INTAKE CLASS | D14: Oct20PT | E14: JAN21PT | F14: MAR21PT | G14: AUG21PT | H14: OCT21PT | I14: JAN22PT | J14: MAR22PT | K14: AUG22PT | L14: OCT22PT | M14: JAN23FT | N14: JAN23PT | O14: MAR23FT | P14: MAR23PT | Q14: AUG23FT | R14: AUG23PT | S14: OCT23FT | T14: OCT23PT | U14: JAN24FT | V14: JAN24PT | W14: MAR24FT | X14: MAR24PT | Y14: AUG24FT | Z14: AUG24PT | AA14: OCT24FT | AB14: OCT24PT | AC14: JAN25FT | AD14: JAN25PT | AE14: MAR25FT | AF14: MAR25PT | AG14: AUG25FT | AH14: AUG25PT | AI14: OCT25FT | AJ14: OCT25PT | AK14: JAN26FT | AL14: JAN26PT | AM14: MAR26FT | AN14: MAR26PT | AO14: AUG26FT | AP14: AUG26PT | AQ14: OCT26FT | AR14: OCT26PT
C15: Link To Moodle Year 2 | E15: JAN23PT | F15: JAN23PT | G15: AUG23PT | H15: OCT23PT | I15: JAN24PT | J15: MAR24PT | K15: AUG24PT | L15: OCT24PT | M15: JAN24FT | N15: JAN25PT | O15: MAR24FT | P15: MAR25PT | Q15: AUG23FT | R15: AUG23PT | S15: Oct23FT | T15: OCT23PT | U15: JAN24FT | V15: JAN24PT | W15: MAR24FT | X15: MAR24PT | Y15: AUG24FT | Z15: AUG24PT | AA15: Oct24FT | AB15: Oct24PT | AC15: Jan25FT | AD15: Jan25PT | AE15: Mar25FT | AF15: Mar25PT | AG15: AUG25FT | AH15: AUG25PT | AI15: OCT25FT | AJ15: OCT25PT | AK15: JAN26FT | AL15: JAN26PT | AM15: MAR26FT | AN15: MAR26PT
B16: Week Start | C16: Calendar Week
A17: August Start | B17: 45516 | C17: Week 33 | D17: 35. PE2 | E17: 31. PE2 | F17: 26. JSF | G17: 21. DVP | H17: 16. SP2 | I17: 11. WFL | J17: 6. JS2 | K17: 0.INTRO | L17: 35. PE2 | M17: 22. DVP | N17: 31. CMS | O17: 12. WFL | P17: 26. INDES | Q17: 0.INTRO | R17: 20. JS1 | S17: 31.AGC1 | T17: 15. SP1 | U17: 22. JS1 | V17: 11. HTML | W17: 12. PME | X17: 6. HTML | Y17: 0.INTRO | Z17: 0.INTRO
B18: =B17+7 -> 45523 | C18: Week 34 | D18: 35. PE2 | E18: 31. PE2 | F18: 27. JSF | G18: 21. DVP | H18: 16. SP2 | I18: 12. WFL | J18: 7. JS2 | K18: 0.INTRO | L18: 35. PE2 | M18: 23. DVP | N18: 31. CMS | O18: 13. SP2 | P18: 26. INDES | Q18: 1.JS2 | R18: 20. JS1 | S18: 32.PE1 | T18: 16. SP1 | U18: 23. JS1 | V18: 11. HTML | W18: 13. PME | X18: 6. HTML | Y18: 1.DES | Z18: 0.INTRO
B19: =B18+7 -> 45530 | C19: Week 35 | D19: 36. PE2 | E19: 32. PE2 | F19: 27. JSF | G19: 22. DVP | H19: 17. SP2 | I19: 12. WFL | J19: 7. JS2 | K19: 1. CSS | L19: 36. PE2 | M19: 24. DVP | N19: 32. CMS | O19: 14. SP2 | P19: 27. INDES | Q19: 2.JS2 | R19: 21. JS1 | S19: 33.PE1 | T19: 16. SP1 | U19: 24. JS1 | V19: 12. PME | W19: 14. SP1 | X19: 7. HTML | Y19: 2.DES | Z19: 1.DES
B20: =B19+7 -> 45537 | C20: Week 36 | D20: 36. PE2 | E20: 32. PE2 | F20: 28. JSF | G20: 22. DVP | H20: 17. SP2 | I20: 13. SP2 | J20: 8. JS2 | K20: 1. CSS | L20: 36. PE2 | M20: 25. JSF | N20: 32. CMS | O20: 15. SP2 | P20: 27. INDES | Q20: 3.JS2 | R20: 21. JS1 | S20: 34.PE1 | T20: 17. SP1 | U20: 25. JS1 | V20: 12. PME | W20: 15. SP1 | X20: 7. HTML | Y20: 3.DES | Z20: 1.DES
B21: =B20+7 -> 45544 | C21: Week 37 | D21: 37. PE2 | E21: 33. PE2 | F21: 28. JSF | G21: 23. DVP | H21: 18. IND | I21: 13. SP2 | J21: 8. JS2 | K21: 2. CSS | L21: 37. PE2 | M21: 26. JSF | N21: 33. PE1 | O21: 16. SP2 | P21: 28. INDES | Q21: 4.JS2 | R21: 22. JS1 | S21: 35.PE1 | T21: 17. SP1 | U21: 26. AGC1 | V21: 13. PME | W21: 16. SP1 | X21: 8. HTML | Y21: 4.DES | Z21: 2.DES
B22: =B21+7 -> 45551 | C22: Week 38 | D22: 37. PE2 | E22: 33. PE2 | F22: 29. JSF | G22: 23. DVP | H22: 18. IND | I22: 14. SP2 | J22: 9. WFL | K22: 2. CSS | L22: 37. PE2 | M22: 27. JSF | N22: 33. PE1 | O22: 17. SP2 | P22: 28. INDES | Q22: 5.JS2 | R22: 22. JS1 | S22: 36.PE1 | T22: 18. JS1 | U22: 27. AGC1 | V22: 13. PME | W22: 17. SP1 | X22: 8. HTML | Y22: 5.DES | Z22: 2.DES
B23: =B22+7 -> 45558 | C23: Week 39 | D23: 38. POR2 | E23: 34. PE2 | F23: 29. JSF | G23: 24. DVP | H23: 19. IND | I23: 14. SP2 | J23: 9. WFL | K23: 3. JS2 | L23: 38. POR2 | M23: 28. JSF | N23: 34. PE1 | O23: 18. IND | P23: 29. INDES | Q23: 6.JS2 | R23: 23. JS1 | S23: 37.PE1 | T23: 18. JS1 | U23: 28. AGC1 | V23: 14. SP1 | W23: 18. JS1 | X23: 9. HTML | Y23: 6.HTML | Z23: 3.DES
B24: =B23+7 -> 45565 | C24: Week 40 | D24: 38. POR2 | E24: 34. PE2 | F24: 30. JSF | G24: 24. DVP | H24: 19. IND | I24: 15. SP2 | J24: 10. WFL | K24: 3. JS2 | L24: 38. POR2 | M24: 29. JSF | N24: 34. PE1 | O24: 19. IND | P24: 29. INDES | Q24: 7.WFL | R24: 23. JS1 | S24: 38.POR1 | T24: 19. JS1 | U24: 29. AGC1 | V24: 14. SP1 | W24: 19. JS1 | X24: 9. HTML | Y24: 7.HTML | Z24: 3.DES
B25: =B24+7 -> 45572 | C25: Week 41 | D25: 39. POR2 | E25: 35. PE2 | F25: 30. JSF | G25: 25. JSF | H25: 20. IND | I25: 15. SP2 | J25: 10. WFL | K25: 4. JS2 | L25: 39. POR2 | M25: 30. JSF | N25: 35. PE1 | O25: 20. IND | P25: 30. CMS | Q25: 8.WFL | R25: 24. JS1 | S25: 39.POR1 | T25: 19. JS1 | U25: 30. AGC1 | V25: 15. SP1 | W25: 20. JS1 | X25: 10. HTML | Y25: 8.HTML | Z25: 4.DES
A26: October Start | B26: =B25+7 -> 45579 | C26: Week 42 | D26: 39. POR2 | E26: 35. PE2 | F26: 31. PE2 | G26: 25. JSF | H26: 20. IND | I26: 16. SP2 | J26: 11. WFL | K26: 4. JS2 | L26: 39. POR2 / 0.INTRO | M26: 31. PE2 | N26: 35. PE1 | O26: 21. DVP | P26: 30. CMS | Q26: 9.WFL | R26: 24. JS1 | S26: 0.INTRO | T26: 20. JS1 | U26: 31. AGC1 | V26: 15. SP1 | W26: 21. JS1 | X26: 10. HTML | Y26: 9.HTML | Z26: 4.DES | AA26: 0.INTRO | AB26: 0.INTRO
B27: =B26+7 -> 45586 | C27: Week 43 | E27: 36. PE2 | F27: 31. PE2 | G27: 26. JSF | H27: 21. DVP | I27: 16. SP2 | J27: 11. WFL | K27: 5. JS2 | L27: 0.INTRO | M27: 32. PE2 | N27: 36. PE1 | O27: 22. DVP | P27: 31. CMS | Q27: 10.CSS | R27: 25. JS1 | S27: 1. JS2 | T27: 20. JS1 | U27: 32. PE1 | V27: 16. SP1 | W27: 22. JS1 | X27: 11. HTML | Y27: 10.HTML | Z27: 5.DES | AA27: 1.DES | AB27: 0.INTRO
B28: =B27+7 -> 45593 | C28: Week 44 | E28: 36. PE2 | F28: 32. PE2 | G28: 26. JSF | H28: 21. DVP | I28: 17. SP2 | J28: 12. WFL | K28: 5. JS2 | L28: 1. CSS | M28: 33. PE2 | N28: 36. PE1 | O28: 23. DVP | P28: 31. CMS | Q28: 11.CSS | R28: 25. JS1 | S28: 2. JS2 | T28: 21. JS1 | U28: 33. PE1 | V28: 16. SP1 | W28: 23. JS1 | X28: 11. HTML | Y28: 11.HTML | Z28: 5.DES | AA28: 2.DES | AB28: 1.DES
B29: =B28+7 -> 45600 | C29: Week 45 | E29: 37. PE2 | F29: 32. PE2 | G29: 27. JSF | H29: 22. DVP | I29: 17. SP2 | J29: 12. WFL | K29: 6. JS2 | L29: 1. CSS | M29: 34. PE2 | N29: 37. PE1 | O29: 24. DVP | P29: 32. CMS | Q29: 12.CSS | R29: 26. AGC1 | S29: 3. JS2 | T29: 21. JS1 | U29: 34. PE1 | V29: 17. SP1 | W29: 24. JS1 | X29: 12. PME | Y29: 12.PME | Z29: 6.HTML | AA29: 3.DES | AB29: 1.DES
B30: =B29+7 -> 45607 | C30: Week 46 | E30: 37. PE2 | F30: 33. PE2 | G30: 27. JSF | H30: 22. DVP | I30: 18. IND | J30: 13. SP2 | K30: 6. JS2 | L30: 2. CSS | M30: 35. PE2 | N30: 37. PE1 | O30: 25. JSF | P30: 32. CMS | Q30: 13.SP2 | R30: 26. AGC1 | S30: 4. JS2 | T30: 22. JS1 | U30: 35. PE1 | V30: 17. SP1 | W30: 25. JS1 | X30: 12. PME | Y30: 13.PME | Z30: 6.HTML | AA30: 4.DES | AB30: 2.DES
B31: =B30+7 -> 45614 | C31: Week 47 | E31: 38. POR2 | F31: 33. PE2 | G31: 28. JSF | H31: 23. DVP | I31: 18. IND | J31: 13. SP2 | K31: 7. JS2 | L31: 2. CSS | M31: 36. PE2 | N31: 38. POR1 | O31: 26. JSF | P31: 33. PE1 | Q31: 14.SP2 | R31: 27. AGC1 | S31: 5. JS2 | T31: 22. JS1 | U31: 36. PE1 | V31: 18. JS1 | W31: 26. AGC1 | X31: 13. PME | Y31: 14.SP1 | Z31: 7.HTML | AA31: 5.DES | AB31: 2.DES
B32: =B31+7 -> 45621 | C32: Week 48 | E32: 38. POR2 | F32: 34. PE2 | G32: 28. JSF | H32: 23. DVP | I32: 19. IND | J32: 14. SP2 | K32: 7. JS2 | L32: 3. JS2 | M32: 37. PE2 | N32: 38. POR1 | O32: 27. JSF | P32: 33. PE1 | Q32: 15.SP2 | R32: 27. AGC1 | S32: 6. JS2 | T32: 23. JS1 | U32: 37. PE1 | V32: 18. JS1 | W32: 27. AGC1 | X32: 13. PME | Y32: 15.SP1 | Z32: 7.HTML | AA32: 6.HTML | AB32: 3.DES
B33: =B32+7 -> 45628 | C33: Week 49 | E33: 39. POR2 | F33: 34. PE2 | G33: 29. JSF | H33: 24. DVP | I33: 19. IND | J33: 14. SP2 | K33: 8. JS2 | L33: 3. JS2 | M33: 38. POR2 | N33: 39. POR1 | O33: 28. JSF | P33: 34. PE1 | Q33: 16.SP2 | R33: 28. AGC1 | S33: 7. WFL | T33: 23. JS1 | U33: 38. POR1 | V33: 19. JS1 | W33: 28. AGC1 | X33: 14. SP1 | Y33: 16.SP1 | Z33: 8.HTML | AA33: 7.HTML | AB33: 3.DES
B34: =B33+7 -> 45635 | C34: Week 50 | E34: 39. POR2 | F34: 35. PE2 | G34: 29. JSF | H34: 24. DVP | I34: 19. IND | J34: 15. SP2 | K34: 8. JS2 | L34: 4. JS2 | M34: 39. POR2 | N34: 39. POR1 | O34: 29. JSF | P34: 34. PE1 | Q34: 17.SP2 | R34: 28. AGC1 | S34: 8. WFL | T34: 24. JS1 | U34: 39. POR1 | V34: 19. JS1 | W34: 29. AGC1 | X34: 14. SP1 | Y34: 17.SP1 | Z34: 8.HTML | AA34: 8.HTML | AB34: 4.DES
B35: =B34+7 -> 45642 | C35: Week 51 | F35: 35. PE2 | G35: 30. JSF | H35: 25. JSF | I35: 20. IND | J35: 15. SP2 | K35: 9. WFL | L35: 4. JS2 | O35: 30. JSF | P35: 35. PE1 | Q35: 18.DVP | R35: 29. AGC1 | S35: 9. WFL | T35: 24. JS1 | V35: 20. JS1 | W35: 30. AGC1 | X35: 15. SP1 | Y35: 18.JS1 | Z35: 9.HTML | AA35: 9.HTML | AB35: 4.DES
A36: Christmas | B36: 45649 | C36: Week 52
B37: 45656 | C37: Week 1
A38: January Start | B38: 45663 | C38: Week 2 | F38: 36. PE2 | G38: 30. JSF | H38: 25. JSF | I38: 20. IND | J38: 16. SP2 | K38: 9. WFL | L38: 5. JS2 | N38: 0. INTRO | O38: 31. PE2 | P38: 35. PE1 | Q38: 19.DVP | R38: 29. AGC1 | S38: 10. CSS | T38: 25. JS1 | U38: 0. INTRO | V38: 20. JS1 | W38: 31. AGC1 | X38: 15. SP1 | Y38: 19.JS1 | Z38: 9.HTML | AA38: 10.HTML | AB38: 5.DES | AC38: 0.INTRO | AD38: 0.INTRO
B39: 45670 | C39: Week 3 | F39: 36. PE2 | G39: 31. PE2 | H39: 26. JSF | I39: 21. DVP | J39: 16. SP2 | K39: 10. WFL | L39: 5. JS2 | N39: 0. INTRO | O39: 32. PE2 | P39: 36. PE1 | Q39: 20.DVP | R39: 30. AGC1 | S39: 11. CSS | T39: 25. JS1 | U39: 1. JS2 | V39: 21. JS1 | W39: 32. PE1 | X39: 16. SP1 | Y39: 20.JS1 | Z39: 10.HTML | AA39: 11.HTML | AB39: 5.DES | AC39: 1.DES | AD39: 0.INTRO
B40: =B39+7 -> 45677 | C40: Week 4 | F40: 37. PE2 | G40: 31. PE2 | H40: 26. JSF | I40: 21. DVP | J40: 17. SP2 | K40: 10. WFL | L40: 6. JS2 | N40: 1. CSS | O40: 33. PE2 | P40: 36. PE1 | Q40: 21.DVP | R40: 30. AGC1 | S40: 12. CSS | T40: 26. JS1 | U40: 2. JS2 | V40: 21. JS1 | W40: 33. PE1 | X40: 16. SP1 | Y40: 21.JS1 | Z40: 10.HTML | AA40: 12.PME | AB40: 6.HTML | AC40: 2.DES | AD40: 1.DES
...

Sheet Sheet2
C6: ='AUG2022 FED'!C15 -> Link To Moodle Year 2 | D6: ='AUG2022 FED'!#REF! -> #REF! | E6: ='AUG2022 FED'!K15 -> AUG24PT | F6: ='AUG2022 FED'!#REF! -> #REF! | G6: ='AUG2022 FED'!#REF! -> #REF! | H6: ='AUG2022 FED'!#REF! -> #REF! | I6: ='AUG2022 FED'!#REF! -> #REF! | J6: ='AUG2022 FED'!#REF! -> #REF! | K6: ='AUG2022 FED'!#REF! -> #REF! | L6: ='AUG2022 FED'!#REF! -> #REF! | M6: ='AUG2022 FED'!#REF! -> #REF! | ... S6: ='AUG2022 FED'!#REF! -> #REF!
A7: =A8-7 -> 45327 | C7: {=_xlfn.XLOOKUP(A7,weeks,'AUG2022 FED'!C15:R99)} -> #VALUE!
A8: 45334 | C8: {=_xlfn.XLOOKUP(A8,weeks,'AUG2022 FED'!C15:R99)} -> #VALUE!
A9: =A8+7 -> 45341 | C9: {=_xlfn.XLOOKUP(A9,weeks,'AUG2022 FED'!C15:R99)} -> #VALUE!
B26: AUG23FT
B27: AUG23PT
B28: OCT23FT
B29: OCT23PT
B30: JAN24FT
B31: JAN24PT
B32: MAR24FT
B33: MAR24PT
B34: AUG24FT
B35: AUG24PT
B36: OCT24FT
B37: OCT24PT

Sheet Templates
A1: Full Time | G1: Part Time
A2: FED1 | B2: FED 2
A3: 0.INTRO | B3: 0. INTRO
A4: 1.DES | B4: 1. JS2
A5: 2.DES | B5: 2. JS2
A6: 3.DES | B6: 3. JS2
A7: 4.DES | B7: 4. JS2
A8: 5.DES | B8: 5. JS2
A9: 6.HTML | B9: 6. JS2
A10: 7.HTML | B10: 7. WFL
A11: 8.HTML | B11: 8. WFL
A12: 9.HTML | B12: 9. WFL
A13: 10.HTML | B13: 10. CSS
... A42: 39.POR1 | B42: 39. POR2
